INFO:django.utils.autoreload:D:\tool\autotool\vulpackage\views.py changed, reloading.
INFO:django.utils.autoreload:D:\tool\autotool\vulpackage\core\common_service.py changed, reloading.
INFO:django.utils.autoreload:D:\tool\autotool\vulpackage\core\common_service.py changed, reloading.
WARNING:django.request:Not Found: /
WARNING:django.request:Not Found: /favicon.ico
INFO:django.utils.autoreload:D:\tool\autotool\vulpackage\scanners\scanner.py changed, reloading.
INFO:django.utils.autoreload:D:\tool\autotool\vulpackage\views.py changed, reloading.
WARNING:django.request:Not Found: /vulpackage/view
WARNING:django.request:Not Found: /vulpackage/view.html
INFO:django.utils.autoreload:D:\tool\autotool\vulpackage\urls.py changed, reloading.
INFO:django.utils.autoreload:D:\tool\autotool\vulpackage\urls.py changed, reloading.
WARNING:django.request:Not Found: /vulpackage/index.html
WARNING:django.request:Not Found: /vulpackage/index.html
WARNING:django.request:Not Found: /vulpackage/index.html
WARNING:django.request:Not Found: /vulpackage/index.html
WARNING:django.request:Not Found: /vulpackage/index.html
WARNING:django.request:Not Found: /vulpackage/index.html
WARNING:django.request:Not Found: /vulpackage/index.html
WARNING:django.request:Not Found: /vulpackage/index.html
WARNING:django.request:Not Found: /vulpackage/index.html
WARNING:django.request:Not Found: /vulpackage/index.html
WARNING:django.request:Not Found: /vulpackage/index.html
WARNING:django.request:Not Found: /vulpackage/index.html
WARNING:django.request:Not Found: /vulpackage/index.html
WARNING:django.request:Not Found: /vulpackage/index.html
WARNING:django.request:Not Found: /vulpackage/index
INFO:django.utils.autoreload:D:\tool\autotool\vulpackage\urls.py changed, reloading.
WARNING:django.request:Not Found: /vulpackag
INFO:django.utils.autoreload:D:\tool\autotool\vulpackage\urls.py changed, reloading.
INFO:django.utils.autoreload:D:\tool\autotool\vulpackage\urls.py changed, reloading.
INFO:django.utils.autoreload:D:\tool\autotool\vulpackage\urls.py changed, reloading.
INFO:django.utils.autoreload:D:\tool\autotool\vulpackage\urls.py changed, reloading.
WARNING:django.request:Not Found: /favicon.ico
WARNING:django.request:Not Found: /
WARNING:django.request:Not Found: /vulpackage/view
WARNING:django.request:Not Found: /vulpackage/view/
WARNING:django.request:Not Found: /vulpackage/view.html
WARNING:django.request:Not Found: /vulpackage/index
INFO:django.utils.autoreload:D:\tool\autotool\vulpackage\urls.py changed, reloading.
WARNING:django.request:Not Found: /vulpackage/index
WARNING:django.request:Not Found: /vulpackage/index
WARNING:django.request:Not Found: /vulpackage/index
WARNING:django.request:Not Found: /vulpackage/view
INFO:django.utils.autoreload:D:\tool\autotool\autotool\urls.py changed, reloading.
INFO:django.utils.autoreload:D:\tool\autotool\autotool\urls.py changed, reloading.
INFO:django.utils.autoreload:D:\tool\autotool\autotool\urls.py changed, reloading.
INFO:django.utils.autoreload:D:\tool\autotool\autotool\urls.py changed, reloading.
WARNING:django.request:Not Found: /vulpackage/view
WARNING:django.request:Not Found: /vulpackage/view/
WARNING:django.request:Not Found: /view/
INFO:django.utils.autoreload:D:\tool\autotool\vulpackage\urls.py changed, reloading.
INFO:django.utils.autoreload:D:\tool\autotool\vulpackage\views.py changed, reloading.
INFO:django.utils.autoreload:D:\tool\autotool\vulpackage\views.py changed, reloading.
INFO:django.utils.autoreload:D:\tool\autotool\vulpackage\views.py changed, reloading.
INFO:django.utils.autoreload:D:\tool\autotool\vulpackage\views.py changed, reloading.
INFO:django.utils.autoreload:D:\tool\autotool\vulpackage\views.py changed, reloading.
INFO:django.utils.autoreload:D:\tool\autotool\vulpackage\views.py changed, reloading.
INFO:django.utils.autoreload:D:\tool\autotool\vulpackage\views.py changed, reloading.
ERROR:django.request:Internal Server Error: /vulpackage/view/
Traceback (most recent call last):
  File "C:\Users\suba\AppData\Local\Programs\Python\Python39\lib\site-packages\django\core\handlers\exception.py", line 47, in inner
    response = get_response(request)
  File "C:\Users\suba\AppData\Local\Programs\Python\Python39\lib\site-packages\django\core\handlers\base.py", line 181, in _get_response
    response = wrapped_callback(request, *callback_args, **callback_kwargs)
  File "D:\tool\autotool\vulpackage\views.py", line 116, in report
    return render(request,'vulpackage/view.html',{"vul":res})
  File "C:\Users\suba\AppData\Local\Programs\Python\Python39\lib\site-packages\django\shortcuts.py", line 19, in render
    content = loader.render_to_string(template_name, context, request, using=using)
  File "C:\Users\suba\AppData\Local\Programs\Python\Python39\lib\site-packages\django\template\loader.py", line 61, in render_to_string
    template = get_template(template_name, using=using)
  File "C:\Users\suba\AppData\Local\Programs\Python\Python39\lib\site-packages\django\template\loader.py", line 15, in get_template
    return engine.get_template(template_name)
  File "C:\Users\suba\AppData\Local\Programs\Python\Python39\lib\site-packages\django\template\backends\django.py", line 34, in get_template
    return Template(self.engine.get_template(template_name), self)
  File "C:\Users\suba\AppData\Local\Programs\Python\Python39\lib\site-packages\django\template\engine.py", line 143, in get_template
    template, origin = self.find_template(template_name)
  File "C:\Users\suba\AppData\Local\Programs\Python\Python39\lib\site-packages\django\template\engine.py", line 125, in find_template
    template = loader.get_template(name, skip=skip)
  File "C:\Users\suba\AppData\Local\Programs\Python\Python39\lib\site-packages\django\template\loaders\base.py", line 29, in get_template
    return Template(
  File "C:\Users\suba\AppData\Local\Programs\Python\Python39\lib\site-packages\django\template\base.py", line 155, in __init__
    self.nodelist = self.compile_nodelist()
  File "C:\Users\suba\AppData\Local\Programs\Python\Python39\lib\site-packages\django\template\base.py", line 193, in compile_nodelist
    return parser.parse()
  File "C:\Users\suba\AppData\Local\Programs\Python\Python39\lib\site-packages\django\template\base.py", line 449, in parse
    raise self.error(token, e)
  File "C:\Users\suba\AppData\Local\Programs\Python\Python39\lib\site-packages\django\template\base.py", line 447, in parse
    filter_expression = self.compile_filter(token.contents)
  File "C:\Users\suba\AppData\Local\Programs\Python\Python39\lib\site-packages\django\template\base.py", line 563, in compile_filter
    return FilterExpression(token, self)
  File "C:\Users\suba\AppData\Local\Programs\Python\Python39\lib\site-packages\django\template\base.py", line 662, in __init__
    raise TemplateSyntaxError("Could not parse the remainder: '%s' "
django.template.exceptions.TemplateSyntaxError: Could not parse the remainder: '%vul%' from '%vul%'
ERROR:django.request:Internal Server Error: /vulpackage/view/
Traceback (most recent call last):
  File "C:\Users\suba\AppData\Local\Programs\Python\Python39\lib\site-packages\django\core\handlers\exception.py", line 47, in inner
    response = get_response(request)
  File "C:\Users\suba\AppData\Local\Programs\Python\Python39\lib\site-packages\django\core\handlers\base.py", line 181, in _get_response
    response = wrapped_callback(request, *callback_args, **callback_kwargs)
  File "D:\tool\autotool\vulpackage\views.py", line 116, in report
    return render(request,'vulpackage/view.html',{"vul":res})
  File "C:\Users\suba\AppData\Local\Programs\Python\Python39\lib\site-packages\django\shortcuts.py", line 19, in render
    content = loader.render_to_string(template_name, context, request, using=using)
  File "C:\Users\suba\AppData\Local\Programs\Python\Python39\lib\site-packages\django\template\loader.py", line 61, in render_to_string
    template = get_template(template_name, using=using)
  File "C:\Users\suba\AppData\Local\Programs\Python\Python39\lib\site-packages\django\template\loader.py", line 15, in get_template
    return engine.get_template(template_name)
  File "C:\Users\suba\AppData\Local\Programs\Python\Python39\lib\site-packages\django\template\backends\django.py", line 34, in get_template
    return Template(self.engine.get_template(template_name), self)
  File "C:\Users\suba\AppData\Local\Programs\Python\Python39\lib\site-packages\django\template\engine.py", line 143, in get_template
    template, origin = self.find_template(template_name)
  File "C:\Users\suba\AppData\Local\Programs\Python\Python39\lib\site-packages\django\template\engine.py", line 125, in find_template
    template = loader.get_template(name, skip=skip)
  File "C:\Users\suba\AppData\Local\Programs\Python\Python39\lib\site-packages\django\template\loaders\base.py", line 29, in get_template
    return Template(
  File "C:\Users\suba\AppData\Local\Programs\Python\Python39\lib\site-packages\django\template\base.py", line 155, in __init__
    self.nodelist = self.compile_nodelist()
  File "C:\Users\suba\AppData\Local\Programs\Python\Python39\lib\site-packages\django\template\base.py", line 193, in compile_nodelist
    return parser.parse()
  File "C:\Users\suba\AppData\Local\Programs\Python\Python39\lib\site-packages\django\template\base.py", line 449, in parse
    raise self.error(token, e)
  File "C:\Users\suba\AppData\Local\Programs\Python\Python39\lib\site-packages\django\template\base.py", line 447, in parse
    filter_expression = self.compile_filter(token.contents)
  File "C:\Users\suba\AppData\Local\Programs\Python\Python39\lib\site-packages\django\template\base.py", line 563, in compile_filter
    return FilterExpression(token, self)
  File "C:\Users\suba\AppData\Local\Programs\Python\Python39\lib\site-packages\django\template\base.py", line 662, in __init__
    raise TemplateSyntaxError("Could not parse the remainder: '%s' "
django.template.exceptions.TemplateSyntaxError: Could not parse the remainder: '%vul%' from '%vul%'
INFO:django.utils.autoreload:D:\tool\autotool\vulpackage\views.py changed, reloading.
INFO:django.utils.autoreload:D:\tool\autotool\vulpackage\views.py changed, reloading.
INFO:django.utils.autoreload:D:\tool\autotool\vulpackage\views.py changed, reloading.
WARNING:django.request:Not Found: /favicon.ico
WARNING:urllib3.connectionpool:Retrying (Retry(total=2, connect=None, read=None, redirect=None, status=None)) after connection broken by 'NewConnectionError('<urllib3.connection.HTTPSConnection object at 0x000002CC42B358E0>: Failed to establish a new connection: [WinError 10061] No connection could be made because the target machine actively refused it')': /api/3/sites
WARNING:urllib3.connectionpool:Retrying (Retry(total=1, connect=None, read=None, redirect=None, status=None)) after connection broken by 'NewConnectionError('<urllib3.connection.HTTPSConnection object at 0x000002CC42B35AC0>: Failed to establish a new connection: [WinError 10061] No connection could be made because the target machine actively refused it')': /api/3/sites
WARNING:urllib3.connectionpool:Retrying (Retry(total=0, connect=None, read=None, redirect=None, status=None)) after connection broken by 'NewConnectionError('<urllib3.connection.HTTPSConnection object at 0x000002CC42B35B80>: Failed to establish a new connection: [WinError 10061] No connection could be made because the target machine actively refused it')': /api/3/sites
ERROR:django.request:Internal Server Error: /vulpackage/start/
Traceback (most recent call last):
  File "C:\Users\suba\AppData\Local\Programs\Python\Python39\lib\site-packages\django\core\handlers\exception.py", line 47, in inner
    response = get_response(request)
  File "C:\Users\suba\AppData\Local\Programs\Python\Python39\lib\site-packages\django\core\handlers\base.py", line 188, in _get_response
    self.check_response(response, callback)
  File "C:\Users\suba\AppData\Local\Programs\Python\Python39\lib\site-packages\django\core\handlers\base.py", line 309, in check_response
    raise ValueError(
ValueError: The view vulpackage.views.start didn't return an HttpResponse object. It returned None instead.
ERROR:django.request:Internal Server Error: /vulpackage/pss/
Traceback (most recent call last):
  File "C:\Users\suba\AppData\Local\Programs\Python\Python39\lib\site-packages\django\core\handlers\exception.py", line 47, in inner
    response = get_response(request)
  File "C:\Users\suba\AppData\Local\Programs\Python\Python39\lib\site-packages\django\core\handlers\base.py", line 181, in _get_response
    response = wrapped_callback(request, *callback_args, **callback_kwargs)
TypeError: pss() takes 0 positional arguments but 1 was given
INFO:django.utils.autoreload:D:\tool\autotool\vulpackage\views.py changed, reloading.
ERROR:django.request:Internal Server Error: /vulpackage/pss/
Traceback (most recent call last):
  File "C:\Users\suba\AppData\Local\Programs\Python\Python39\lib\site-packages\django\core\handlers\exception.py", line 47, in inner
    response = get_response(request)
  File "C:\Users\suba\AppData\Local\Programs\Python\Python39\lib\site-packages\django\core\handlers\base.py", line 188, in _get_response
    self.check_response(response, callback)
  File "C:\Users\suba\AppData\Local\Programs\Python\Python39\lib\site-packages\django\core\handlers\base.py", line 309, in check_response
    raise ValueError(
ValueError: The view vulpackage.views.pss didn't return an HttpResponse object. It returned None instead.
ERROR:django.request:Internal Server Error: /vulpackage/pss/
Traceback (most recent call last):
  File "C:\Users\suba\AppData\Local\Programs\Python\Python39\lib\site-packages\django\core\handlers\exception.py", line 47, in inner
    response = get_response(request)
  File "C:\Users\suba\AppData\Local\Programs\Python\Python39\lib\site-packages\django\core\handlers\base.py", line 188, in _get_response
    self.check_response(response, callback)
  File "C:\Users\suba\AppData\Local\Programs\Python\Python39\lib\site-packages\django\core\handlers\base.py", line 309, in check_response
    raise ValueError(
ValueError: The view vulpackage.views.pss didn't return an HttpResponse object. It returned None instead.
ERROR:django.request:Internal Server Error: /vulpackage/pss/
Traceback (most recent call last):
  File "C:\Users\suba\AppData\Local\Programs\Python\Python39\lib\site-packages\django\core\handlers\exception.py", line 47, in inner
    response = get_response(request)
  File "C:\Users\suba\AppData\Local\Programs\Python\Python39\lib\site-packages\django\core\handlers\base.py", line 188, in _get_response
    self.check_response(response, callback)
  File "C:\Users\suba\AppData\Local\Programs\Python\Python39\lib\site-packages\django\core\handlers\base.py", line 309, in check_response
    raise ValueError(
ValueError: The view vulpackage.views.pss didn't return an HttpResponse object. It returned None instead.
ERROR:django.request:Internal Server Error: /vulpackage/pss/
Traceback (most recent call last):
  File "C:\Users\suba\AppData\Local\Programs\Python\Python39\lib\site-packages\django\core\handlers\exception.py", line 47, in inner
    response = get_response(request)
  File "C:\Users\suba\AppData\Local\Programs\Python\Python39\lib\site-packages\django\core\handlers\base.py", line 188, in _get_response
    self.check_response(response, callback)
  File "C:\Users\suba\AppData\Local\Programs\Python\Python39\lib\site-packages\django\core\handlers\base.py", line 309, in check_response
    raise ValueError(
ValueError: The view vulpackage.views.pss didn't return an HttpResponse object. It returned None instead.
ERROR:django.request:Internal Server Error: /vulpackage/pss/
Traceback (most recent call last):
  File "C:\Users\suba\AppData\Local\Programs\Python\Python39\lib\site-packages\django\core\handlers\exception.py", line 47, in inner
    response = get_response(request)
  File "C:\Users\suba\AppData\Local\Programs\Python\Python39\lib\site-packages\django\core\handlers\base.py", line 188, in _get_response
    self.check_response(response, callback)
  File "C:\Users\suba\AppData\Local\Programs\Python\Python39\lib\site-packages\django\core\handlers\base.py", line 309, in check_response
    raise ValueError(
ValueError: The view vulpackage.views.pss didn't return an HttpResponse object. It returned None instead.
ERROR:django.request:Internal Server Error: /vulpackage/pss/
Traceback (most recent call last):
  File "C:\Users\suba\AppData\Local\Programs\Python\Python39\lib\site-packages\django\core\handlers\exception.py", line 47, in inner
    response = get_response(request)
  File "C:\Users\suba\AppData\Local\Programs\Python\Python39\lib\site-packages\django\core\handlers\base.py", line 188, in _get_response
    self.check_response(response, callback)
  File "C:\Users\suba\AppData\Local\Programs\Python\Python39\lib\site-packages\django\core\handlers\base.py", line 309, in check_response
    raise ValueError(
ValueError: The view vulpackage.views.pss didn't return an HttpResponse object. It returned None instead.
ERROR:django.request:Internal Server Error: /vulpackage/pss/
Traceback (most recent call last):
  File "C:\Users\suba\AppData\Local\Programs\Python\Python39\lib\site-packages\django\core\handlers\exception.py", line 47, in inner
    response = get_response(request)
  File "C:\Users\suba\AppData\Local\Programs\Python\Python39\lib\site-packages\django\core\handlers\base.py", line 188, in _get_response
    self.check_response(response, callback)
  File "C:\Users\suba\AppData\Local\Programs\Python\Python39\lib\site-packages\django\core\handlers\base.py", line 309, in check_response
    raise ValueError(
ValueError: The view vulpackage.views.pss didn't return an HttpResponse object. It returned None instead.
ERROR:django.request:Internal Server Error: /vulpackage/pss/
Traceback (most recent call last):
  File "C:\Users\suba\AppData\Local\Programs\Python\Python39\lib\site-packages\django\core\handlers\exception.py", line 47, in inner
    response = get_response(request)
  File "C:\Users\suba\AppData\Local\Programs\Python\Python39\lib\site-packages\django\core\handlers\base.py", line 188, in _get_response
    self.check_response(response, callback)
  File "C:\Users\suba\AppData\Local\Programs\Python\Python39\lib\site-packages\django\core\handlers\base.py", line 309, in check_response
    raise ValueError(
ValueError: The view vulpackage.views.pss didn't return an HttpResponse object. It returned None instead.
ERROR:django.request:Internal Server Error: /vulpackage/pss/
Traceback (most recent call last):
  File "C:\Users\suba\AppData\Local\Programs\Python\Python39\lib\site-packages\django\core\handlers\exception.py", line 47, in inner
    response = get_response(request)
  File "C:\Users\suba\AppData\Local\Programs\Python\Python39\lib\site-packages\django\core\handlers\base.py", line 188, in _get_response
    self.check_response(response, callback)
  File "C:\Users\suba\AppData\Local\Programs\Python\Python39\lib\site-packages\django\core\handlers\base.py", line 309, in check_response
    raise ValueError(
ValueError: The view vulpackage.views.pss didn't return an HttpResponse object. It returned None instead.
WARNING:django.request:Not Found: /start
WARNING:django.request:Not Found: /start
WARNING:django.request:Not Found: /vulpackage/vulpackage/start
WARNING:django.request:Not Found: /vulpackage/vulpackage/start
WARNING:django.request:Not Found: /vulpackage/vulpackage/start
WARNING:django.request:Not Found: /
WARNING:django.request:Not Found: /vulpackage/vulpackage/start
WARNING:django.request:Not Found: /start
WARNING:django.request:Not Found: /start
WARNING:urllib3.connectionpool:Retrying (Retry(total=2, connect=None, read=None, redirect=None, status=None)) after connection broken by 'NewConnectionError('<urllib3.connection.HTTPSConnection object at 0x000001CC6C9F01C0>: Failed to establish a new connection: [WinError 10061] No connection could be made because the target machine actively refused it')': /api/3/sites
WARNING:urllib3.connectionpool:Retrying (Retry(total=1, connect=None, read=None, redirect=None, status=None)) after connection broken by 'NewConnectionError('<urllib3.connection.HTTPSConnection object at 0x000001CC6C9F0490>: Failed to establish a new connection: [WinError 10061] No connection could be made because the target machine actively refused it')': /api/3/sites
WARNING:urllib3.connectionpool:Retrying (Retry(total=0, connect=None, read=None, redirect=None, status=None)) after connection broken by 'NewConnectionError('<urllib3.connection.HTTPSConnection object at 0x000001CC6C9F05E0>: Failed to establish a new connection: [WinError 10061] No connection could be made because the target machine actively refused it')': /api/3/sites
ERROR:django.request:Internal Server Error: /vulpackage/start/
Traceback (most recent call last):
  File "C:\Users\suba\AppData\Local\Programs\Python\Python39\lib\site-packages\django\core\handlers\exception.py", line 47, in inner
    response = get_response(request)
  File "C:\Users\suba\AppData\Local\Programs\Python\Python39\lib\site-packages\django\core\handlers\base.py", line 188, in _get_response
    self.check_response(response, callback)
  File "C:\Users\suba\AppData\Local\Programs\Python\Python39\lib\site-packages\django\core\handlers\base.py", line 309, in check_response
    raise ValueError(
ValueError: The view vulpackage.views.start didn't return an HttpResponse object. It returned None instead.
INFO:django.utils.autoreload:D:\tool\autotool\vulpackage\urls.py changed, reloading.
ERROR:django.request:Internal Server Error: /vulpackage/pss/
Traceback (most recent call last):
  File "C:\Users\suba\AppData\Local\Programs\Python\Python39\lib\site-packages\django\core\handlers\exception.py", line 47, in inner
    response = get_response(request)
  File "C:\Users\suba\AppData\Local\Programs\Python\Python39\lib\site-packages\django\core\handlers\base.py", line 188, in _get_response
    self.check_response(response, callback)
  File "C:\Users\suba\AppData\Local\Programs\Python\Python39\lib\site-packages\django\core\handlers\base.py", line 309, in check_response
    raise ValueError(
ValueError: The view vulpackage.views.pss didn't return an HttpResponse object. It returned None instead.
ERROR:django.request:Internal Server Error: /vulpackage/pause/
Traceback (most recent call last):
  File "C:\Users\suba\AppData\Local\Programs\Python\Python39\lib\site-packages\django\core\handlers\exception.py", line 47, in inner
    response = get_response(request)
  File "C:\Users\suba\AppData\Local\Programs\Python\Python39\lib\site-packages\django\core\handlers\base.py", line 188, in _get_response
    self.check_response(response, callback)
  File "C:\Users\suba\AppData\Local\Programs\Python\Python39\lib\site-packages\django\core\handlers\base.py", line 309, in check_response
    raise ValueError(
ValueError: The view vulpackage.views.pause didn't return an HttpResponse object. It returned None instead.
INFO:django.utils.autoreload:D:\tool\autotool\vulpackage\views.py changed, reloading.
INFO:django.utils.autoreload:D:\tool\autotool\vulpackage\views.py changed, reloading.
WARNING:urllib3.connectionpool:Retrying (Retry(total=2, connect=None, read=None, redirect=None, status=None)) after connection broken by 'NewConnectionError('<urllib3.connection.HTTPSConnection object at 0x000001FF2217D220>: Failed to establish a new connection: [WinError 10061] No connection could be made because the target machine actively refused it')': /api/3/sites
WARNING:urllib3.connectionpool:Retrying (Retry(total=1, connect=None, read=None, redirect=None, status=None)) after connection broken by 'NewConnectionError('<urllib3.connection.HTTPSConnection object at 0x000001FF2217D1C0>: Failed to establish a new connection: [WinError 10061] No connection could be made because the target machine actively refused it')': /api/3/sites
WARNING:urllib3.connectionpool:Retrying (Retry(total=0, connect=None, read=None, redirect=None, status=None)) after connection broken by 'NewConnectionError('<urllib3.connection.HTTPSConnection object at 0x000001FF2217D400>: Failed to establish a new connection: [WinError 10061] No connection could be made because the target machine actively refused it')': /api/3/sites
INFO:django.utils.autoreload:D:\tool\autotool\vulpackage\views.py changed, reloading.
INFO:django.utils.autoreload:D:\tool\autotool\vulpackage\urls.py changed, reloading.
